<?xml version="1.0"?>
<robot xmlns:xacro="http://www.ros.org/wiki/xacro" name="dd_robot">
	
	<xacro:arg name="robot_name" default="dd_robot"/>

	<!-- Base Link (Robot Body) -->
	<link name="base_link">
		<visual>
			<origin xyz="0 0 0" rpy="0 0 0" />
			<geometry>
				<box size="0.5 0.5 0.25" />
			</geometry>
			<material name="blue">
				<color rgba="0 0.5 1 1"/>
			</material>
		</visual>
		<!-- Collision and Inertia -->
		<collision>
      <origin xyz="0 0 0" rpy="0 0 0" />
      <geometry>
          <box size="0.5 0.5 0.25"/>
      </geometry>
    </collision>
    <inertial>
      <mass value="5"/>
      <inertia ixx="0.13" ixy="0.0" ixz="0.0" iyy="0.21" iyz="0.0" izz="0.13"/>
    </inertial>
	</link>

	<!-- Right Wheel -->
	<link name="right_wheel">
		<visual>
			<origin xyz="0 0 0" rpy="1.570795 0 0" />
			<geometry>
				<cylinder length="0.1" radius="0.2" />
			</geometry>
			<material name="black">
				<color rgba="0.05 0.05 0.05 1"/>
			</material>
		</visual>
		<!-- Collision and Inertia -->
		<collision>
      <origin xyz="0 0 0" rpy="1.570795 0 0" />
      <geometry>
          <cylinder length="0.1" radius="0.2" />
      </geometry>
    </collision>
    <inertial>
      <mass value="0.5"/>
      <inertia ixx="0.01" ixy="0.0" ixz="0.0" iyy="0.005" iyz="0.0" izz="0.005"/>
    </inertial>
	</link>
	<joint name="joint_right_wheel" type="continuous">
		<parent link="base_link"/>
		<child link="right_wheel"/>
		<origin xyz="0 -0.30 0" rpy="0 0 0"/>
		<axis xyz="0 1 0"/>
	</joint>

	<!-- Left Wheel -->
	<link name="left_wheel">
		<visual>
			<origin xyz="0 0 0" rpy="1.570795 0 0" />
			<geometry>
				<cylinder length="0.1" radius="0.2" />
			</geometry>
			<material name="black">
				<color rgba="0.05 0.05 0.05 1"/>
			</material>
		</visual>
		<!-- Collision and Inertia -->
		<collision>
      <origin xyz="0 0 0" rpy="1.570795 0 0" />
      <geometry>
          <cylinder length="0.1" radius="0.2" />
      </geometry>
    </collision>
    <inertial>
      <mass value="0.5"/>
      <inertia ixx="0.01" ixy="0.0" ixz="0.0" iyy="0.005" iyz="0.0" izz="0.005"/>
    </inertial>
	</link>
	<joint name="joint_left_wheel" type="continuous">
		<parent link="base_link"/>
		<child link="left_wheel"/>
		<origin xyz="0 0.30 0" rpy="0 0 0"/>
		<axis xyz="0 1 0"/>
	</joint>

	<!-- Caster Wheel -->
	<link name="caster">
		<visual>
			<origin xyz="0.0 0 0" rpy="0 0 0" />
			<geometry>
				<sphere radius="0.05" />
			</geometry>
			<material name="darkgray">
				<color rgba="0.2 0.2 0.2 1"/>
			</material>
		</visual>
		<!-- Collision and Inertia -->
		<collision>
      <origin xyz="0 0 0" rpy="0 0 0" />
      <geometry>
        <sphere radius="0.05" />
      </geometry>
    </collision>
    <inertial>
      <mass value="0.5"/>
      <inertia ixx="0.0001" ixy="0.0" ixz="0.0" iyy="0.0001" iyz="0.0" izz="0.0001"/>
    </inertial>
	</link>
	<joint name="joint_caster" type="fixed">
		<parent link="base_link"/>
		<child link="caster"/>
		<origin xyz="-0.2 0 -0.125" rpy="0 0 0"/>
	</joint>

	<!-- Communicating with Gazebo -->
	<gazebo>
		<plugin filename="gz-sim-diff-drive-system" name="gz::sim::systems::DiffDrive">
			<left_joint>joint_left_wheel</left_joint>
			<right_joint>joint_right_wheel</right_joint>
			<wheel_separation>0.6</wheel_separation>
			<wheel_radius>0.2</wheel_radius>
			<max_linear_acceleration>1.0</max_linear_acceleration>
			<odom_publish_frequency>50</odom_publish_frequency>
			
			<topic>/model/$(arg robot_name)/cmd_vel</topic>
			<odom_topic>/model/$(arg robot_name)/odometry</odom_topic>
			<tf_topic>/model/$(arg robot_name)/tf</tf_topic>
			<frame_id>$(arg robot_name)/odom</frame_id>
			<child_frame_id>$(arg robot_name)/base_link</child_frame_id>
		</plugin>
		<plugin filename="gz-sim-joint-state-publisher-system" name="gz::sim::systems::JointStatePublisher">
			<joint_name>joint_left_wheel</joint_name>
			<joint_name>joint_right_wheel</joint_name>
		</plugin>
	    <plugin filename="gz-sim-pose-publisher-system" name="gz::sim::systems::PosePublisher">
    	  	<publish_link_pose>false</publish_link_pose>
      	  	<publish_visual_pose>false</publish_visual_pose>
     	 	<publish_collision_pose>false</publish_collision_pose>
      		<publish_sensor_pose>false</publish_sensor_pose>
       	   	<publish_model_pose>true</publish_model_pose>
      		<update_frequency>10</update_frequency>
    	</plugin>
	</gazebo>

	<gazebo reference="caster">
		<mul1>0.0</mul1>
		<mul2>0.0</mul2>
	</gazebo>

</robot>
